<?xml version="1.0" ?>
<sdf version="1.5">
  <model name="jar_hollow">
    <link name="link">
      <gravity>true</gravity>
      <inertial>
        <pose>0 0 0 0 0 0</pose>
        <mass>0.1</mass>
        <inertia>
          <ixx>0.00040</ixx>
          <ixy>0</ixy>
          <ixz>0</ixz>
          <iyy>0.00040</iyy>
          <iyz>0</iyz>
          <izz>0.00012</izz>
        </inertia>
      </inertial>
      <collision name="collision1">
        <pose>0 0 0 0 0 0</pose>
        <geometry>
          <mesh>
            <uri>model://jar_hollow/meshes/jar_hollow_side.dae</uri>
          </mesh>
        </geometry>
        <surface>
          <friction>
            <ode>
              <mu>1.0</mu>
              <mu2>1.0</mu2>
            </ode>
          </friction>
          <contact>
            <ode>
              <kp>10000000.0</kp>
              <kd>1.0</kd>
              <min_depth>0.001</min_depth>
              <max_vel>0.1</max_vel>
            </ode>
          </contact>
        </surface>
      </collision>
      <collision name="collision2">
        <pose>0 0 0 0 0 1.570796327</pose>
        <geometry>
          <mesh>
            <uri>model://jar_hollow/meshes/jar_hollow_side.dae</uri>
          </mesh>
        </geometry>
        <surface>
          <friction>
            <ode>
              <mu>1.0</mu>
              <mu2>1.0</mu2>
            </ode>
          </friction>
          <contact>
            <ode>
              <kp>10000000.0</kp>
              <kd>1.0</kd>
              <min_depth>0.001</min_depth>
              <max_vel>0.1</max_vel>
            </ode>
          </contact>
        </surface>
      </collision>
      <collision name="collision3">
        <pose>0 0 0 0 0 3.14159265359</pose>
        <geometry>
          <mesh>
            <uri>model://jar_hollow/meshes/jar_hollow_side.dae</uri>
          </mesh>
        </geometry>
        <surface>
          <friction>
            <ode>
              <mu>1.0</mu>
              <mu2>1.0</mu2>
            </ode>
          </friction>
          <contact>
            <ode>
              <kp>10000000.0</kp>
              <kd>1.0</kd>
              <min_depth>0.001</min_depth>
              <max_vel>0.1</max_vel>
            </ode>
          </contact>
        </surface>
      </collision>
      <collision name="collision4">
        <pose>0 0 0 0 0 -1.570796327</pose>
        <geometry>
          <mesh>
            <uri>model://jar_hollow/meshes/jar_hollow_side.dae</uri>
          </mesh>
        </geometry>
        <surface>
          <friction>
            <ode>
              <mu>1.0</mu>
              <mu2>1.0</mu2>
            </ode>
          </friction>
          <contact>
            <ode>
              <kp>10000000.0</kp>
              <kd>1.0</kd>
              <min_depth>0.001</min_depth>
              <max_vel>0.1</max_vel>
            </ode>
          </contact>
        </surface>
      </collision>
      <collision name="collision5">
        <pose>0 0 0 0 0 0</pose>
        <geometry>
          <mesh>
            <uri>model://jar_hollow/meshes/jar_hollow_bottom_convex.dae</uri>
          </mesh>
        </geometry>
        <surface>
          <friction>
            <ode>
              <mu>1.0</mu>
              <mu2>1.0</mu2>
            </ode>
          </friction>
          <contact>
            <ode>
              <kp>10000000.0</kp>
              <kd>1.0</kd>
              <min_depth>0.001</min_depth>
              <max_vel>0.1</max_vel>
            </ode>
          </contact>
        </surface>
      </collision>
      <visual name="visual1">
        <pose>0 0 0 0 0 0</pose>
        <geometry>
          <mesh>
            <uri>model://jar_hollow/meshes/jar_hollow_side.dae</uri>
          </mesh>
        </geometry>
        <material>
          <diffuse>0.7 0.7 0.7 0.5</diffuse>
        </material>
      </visual>
      <visual name="visual2">
        <pose>0 0 0 0 0 1.570796327</pose>
        <geometry>
          <mesh>
            <uri>model://jar_hollow/meshes/jar_hollow_side.dae</uri>
          </mesh>
        </geometry>
        <material>
          <diffuse>0.7 0.7 0.7 0.5</diffuse>
        </material>
      </visual>
      <visual name="visual3">
        <pose>0 0 0 0 0 3.14159265359</pose>
        <geometry>
          <mesh>
            <uri>model://jar_hollow/meshes/jar_hollow_side.dae</uri>
          </mesh>
        </geometry>
        <material>
          <diffuse>0.7 0.7 0.7 0.5</diffuse>
        </material>
      </visual>
      <visual name="visual4">
        <pose>0 0 0 0 0 -1.570796327</pose>
        <geometry>
          <mesh>
            <uri>model://jar_hollow/meshes/jar_hollow_side.dae</uri>
          </mesh>
        </geometry>
        <material>
          <diffuse>0.7 0.7 0.7 0.5</diffuse>
        </material>
      </visual>
      <visual name="visual5">
        <pose>0 0 0 0 0 0</pose>
        <geometry>
          <mesh>
            <uri>model://jar_hollow/meshes/jar_hollow_bottom_convex.dae</uri>
          </mesh>
        </geometry>
      </visual>
    </link>

    <joint name="cap_hinge" type="revolute">
      <parent>link</parent>
      <child>hidden_cap</child>
      <axis>
        <xyz>1 0 0</xyz>
        <limit>
          <lower>-1.57</lower>
          <upper>0</upper>
        </limit>
        <dynamics>
          <friction>1</friction>
        </dynamics>
      </axis>
      <pose>0 -0.035 0.07 0 0 0</pose>
    </joint>

    <link name="hidden_cap">
      <gravity>false</gravity>
      <inertial>
        <pose frame=''>0 0 0.07 0 0 0</pose>
        <mass>0.02</mass>
        <inertia>
          <ixx>0.00015</ixx>
          <ixy>0</ixy>
          <ixz>0</ixz>
          <iyy>0.00015</iyy>
          <iyz>0</iyz>
          <izz>0.00003</izz>
        </inertia>
      </inertial>
      <collision name="collision1">
        <pose frame=''>0 0 0.07 0 0 0</pose>
        <geometry>
          <box>
            <size>0.05 0.05 0.006</size>
          </box>
        </geometry>
        <surface>
          <friction>
            <ode>
              <mu>1.0</mu>
              <mu2>1.0</mu2>
            </ode>
          </friction>
          <contact>
            <ode>
              <kp>10000000.0</kp>
              <kd>1.0</kd>
              <min_depth>0.001</min_depth>
              <max_vel>0.1</max_vel>
            </ode>
          </contact>
        </surface>
      </collision>
      <!-- This link should not be visible -->
      <!--
      <visual name="visual1">
        <pose frame=''>0 0 0.07 0 0 0</pose>
        <geometry>
          <box>
            <size>0.05 0.05 0.006</size>
          </box>
        </geometry>
      </visual>
      -->
    </link>

  </model>
</sdf>
